<?xml version="1.0"?>

<robot name="sailboat" xmlns:xacro="http://ros.org/wiki/xacro">

    <!-- scale for sail and tail model -->
    <xacro:property name="scale_model" value="0.006"/>

    <xacro:arg name="windType" default="global" />
    <xacro:arg name="waterType" default="global" />
    <xacro:property name="windType" value="$(arg windType)" />
    <xacro:property name="waterType" value="$(arg waterType)" />

    <xacro:property name="windType" value="global"/>
    <xacro:include filename="$(find usv_sim)/xacro/boat_subdivided4.xacro" />
	  <xacro:include filename="$(find usv_sim)/xacro/anemometer.xacro" />
    <xacro:include filename="$(find usv_sim)/xacro/gps.xacro" />
		<xacro:include filename="$(find usv_sim)/xacro/imu.xacro" /> 


    <xacro:rudder_xacro/>

    <!-- Defining sail model -->

    <link name="sail">
		<inertial>
		    	<origin rpy="0 0 0" xyz="-0.3 0 0.4"/>
			<mass value="1" />
			<inertia
			  ixx="0.4708"
			  ixy="0.0"
			  iyy="0.5208"
			  ixz="0.0"
			  iyz="0.0"
			  izz="0.0508"/>
		</inertial>

	    <collision name="collision">
            <geometry>
              <mesh filename="package://usv_sim/meshes/simpleHull3/Wing_Eppler479.dae" scale="0.006 0.006 0.006"/>
            </geometry>
	<!--	<origin rpy="1.570796327 0 -1.570796327" xyz="0 0.1 0.3"/> -->
            <origin rpy="1.570796327 0 ${PI}" xyz="0.1 0 0.3"/>  
	    </collision>

	    <visual name="visual">
            <geometry>
              <mesh filename="package://usv_sim/meshes/simpleHull3/Wing_Eppler479.dae" scale="0.006 0.006 0.006"/>
            </geometry>-
	<!--	<origin rpy="1.570796327 0 -1.570796327" xyz="0 0.1 0.3"/> -->
            <origin rpy="1.570796327 0 ${PI}" xyz="0.1 0 0.3"/> 
	    </visual> 
    </link>


    <joint name="sail_joint" type="revolute">
        <parent link="base_link"/>
        <child link="sail"/>
        <origin rpy="0 0 0" xyz="0.38 0 0.10"/>
        <dynamics damping="1.0"/>
        <axis xyz="0 0 1"/>
        <limit effort="100" velocity="70" lower="-${PI}" upper="${PI}" />
    </joint> 

    <!-- Defining tail model -->

    <link name="tail">
		<inertial>
		    	<origin rpy="0 0 0" xyz="-0.3 0 0.4"/>
			<mass value="1" />
			<inertia
			  ixx="0.4708"
			  ixy="0.0"
			  iyy="0.5208"
			  ixz="0.0"
			  iyz="0.0"
			  izz="0.0508"/>
		</inertial>

	    <collision name="collision">
            <geometry>
              <mesh filename="package://usv_sim/meshes/simpleHull3/Tail_Eppler479.dae" scale="0.006 0.006 0.006"/>
            </geometry>
	<!--	<origin rpy="1.570796327 0 -1.570796327" xyz="0.6 -0.55 -0.045"/> -->
            <origin rpy="1.570796327 0 ${PI}" xyz="0.028 0 -0.045"/> 
	    </collision>

	    <visual name="visual">
            <geometry>
              <mesh filename="package://usv_sim/meshes/simpleHull3/Tail_Eppler479.dae" scale="0.006 0.006 0.006"/>
            </geometry>
	<!--	<origin rpy="1.570796327 0 -1.570796327" xyz="0.6 -0.55 -0.045"/> -->
            <origin rpy="1.570796327 0 ${PI}" xyz="0.028 0 -0.045"/> 
	    </visual>
    </link>


    <joint name="tail_joint" type="revolute">
        <parent link="sail"/>
        <child link="tail"/>
        <origin rpy="0 0 0" xyz="-0.60 0 0.80"/>
        <dynamics damping="1.0"/>
        <axis xyz="0 0 1"/>
        <limit effort="10000" velocity="0" lower="-${PI}" upper="${PI}" />
    </joint>


    <!-- Defining keel model -->

    <link name="keel">
	<inertial>
		<mass value="30" />
		<inertia
		  ixx="0.4708"
		  ixy="0.0"
		  iyy="0.5208"
		  ixz="0.0"
		  iyz="0.0"
		  izz="0.0508"/>
	</inertial>
	<collision name="collision">
		<geometry>
			<box size="0.25 0.02 0.5" />
		</geometry>
		<origin rpy="0 0 0" xyz="0 0 0"/>

	</collision>

	<visual name="visual">
		<geometry>
			<mesh filename="package://usv_sim/meshes/simpleHull3/box.dae" scale="0.25 0.02 0.5"/>
		</geometry>
		<origin rpy="0 0 0" xyz="0 0 0"/>
	</visual>
</link>

    <joint name="keel_joint" type="revolute">
        <parent link="base_link"/>
        <child link="keel"/>
        <origin rpy="0 0 0" xyz="0 0 -0.35"/>
        <dynamics damping="1.0"/>
        <axis xyz="0 0 1"/>
        <limit effort="30" velocity="5" lower="0" upper="0" />
    </joint>


    <link name="converter">
    <inertial>
      <origin rpy="0 0 0" xyz="0 0 0"/>
      <mass value="1"/> <!-- kilogram -->
      <inertia
        ixx="0"
        ixy="0"
        iyy="0"
        ixz="0"
        iyz="0"
        izz="0"/>
    </inertial>

      <collision name="collision">
            <geometry>
              <mesh filename="package://usv_sim/meshes/simpleHull3/converter_DC_DC.dae" scale="0.5 0.5 0.5"/>
            </geometry>
            <origin rpy="${PI} 0 1.570796327" xyz="-0.5 0 0.08"/>
      </collision>

      <visual name="visual">
            <geometry>
              <mesh filename="package://usv_sim/meshes/simpleHull3/converter_DC_DC.dae" scale="0.5 0.5 0.5"/>
            </geometry>
            <origin rpy="${PI} 0 1.570796327" xyz="-0.5 0 0.08"/>
      </visual>
    </link>


    <joint name="converter_joint" type="revolute">
        <parent link="base_link"/>
        <child link="converter"/>
        <origin rpy="0 0 0" xyz="00 0 0"/>
        <dynamics damping="1.0"/>
        <axis xyz="0 0 1"/>
        <limit effort="100" velocity="70" lower="-${PI}" upper="${PI}" />
    </joint>

    <link name="imu">
    <inertial>
      <origin rpy="0 0 0" xyz="0 0 0"/>
      <mass value="1"/> <!-- kilogram -->
      <inertia
        ixx="0"
        ixy="0"
        iyy="0"
        ixz="0"
        iyz="0"
        izz="0"/>
    </inertial>

      <collision name="collision">
            <geometry>
              <mesh filename="package://usv_sim/meshes/simpleHull3/imu.dae" scale="0.002 0.002 0.002"/>
            </geometry>
            <origin rpy="${PI} ${-PI} 1.570796327" xyz="-0.5 0.08 0.08"/>
      </collision>

      <visual name="visual">
            <geometry>
              <mesh filename="package://usv_sim/meshes/simpleHull3/imu.dae" scale="0.002 0.002 0.002"/>
            </geometry>
            <origin rpy="${PI} ${-PI} 1.570796327" xyz="-0.5 0.08 0.08"/>
      </visual>
    </link>


    <joint name="imu_joint_" type="revolute">
        <parent link="base_link"/>
        <child link="imu"/>
        <origin rpy="0 0 0" xyz="00 0 0"/>
        <dynamics damping="1.0"/>
        <axis xyz="0 0 1"/>
        <limit effort="100" velocity="70" lower="-${PI}" upper="${PI}" />
    </joint>

    <link name="solar_panel">
    <inertial>
      <origin rpy="0 0 0" xyz="0 0 0"/>
      <mass value="1"/> <!-- kilogram -->
      <inertia
        ixx="0"
        ixy="0"
        iyy="0"
        ixz="0"
        iyz="0"
        izz="0"/>
    </inertial>

      <collision name="collision">
            <geometry>
              <mesh filename="package://usv_sim/meshes/simpleHull3/solar_panel.dae" scale="0.0002 0.0002 0.0002"/>
            </geometry>
            <origin rpy="${PI} 0 1.570796327" xyz="-0.5 0 0.08"/>
      </collision>

      <visual name="visual">
            <geometry>
              <mesh filename="package://usv_sim/meshes/simpleHull3/solar_panel.dae" scale="0.0002 0.0002 0.0002"/>
            </geometry>
            <origin rpy="${PI} 0 1.570796327" xyz="-0.5 0 0.08"/>
      </visual>
    </link>


    <joint name="solar_panel_joint" type="revolute">
        <parent link="base_link"/>
        <child link="solar_panel"/>
        <origin rpy="0 0 0" xyz="00 0 0"/>
        <dynamics damping="1.0"/>
        <axis xyz="0 0 1"/>
        <limit effort="100" velocity="70" lower="-${PI}" upper="${PI}" />
    </joint>


    <!-- Plugin list -->
  <gazebo>

	<plugin name="usv_sail_plugin" filename="libfoil_dynamics_plugin.so">
		<link_type>sail</link_type>
		<a0>0</a0>
		<cla>3.0</cla>
		<cda>3.0</cda>
		<cma>-1.8</cma>
		<alpha_stall>0.785</alpha_stall>
		<cla_stall>-3.85</cla_stall>
		<cda_stall>-0.9233984055</cda_stall>
		<cma_stall>0</cma_stall>
		<cp>0 0 0</cp>
		<joint_name>sail_joint</joint_name>
		<area>1.44</area>
		<fluid_density>1.2041</fluid_density>
		<forward>-1 0 0</forward>
		<upward>0 1 0</upward>
		<link_name>sail</link_name>
		<fluidVelocity>${windType}</fluidVelocity>
      </plugin>


    <plugin name="usv_sail_plugin" filename="libfoil_dynamics_plugin.so">
  		<link_type>tail</link_type>
      <a0>0</a0>
			<cla>5.9917</cla>
			<cda>0.5526</cda>
			<cma>-0.05</cma>
			<alpha_stall>0.148351444</alpha_stall>
			<cla_stall>-3.4149</cla_stall>
			<cda_stall>0.6424</cda_stall>
			<cma_stall>0.2</cma_stall>
  		<cp>0.850 0 1.25</cp>
  		<joint_name>tail_joint</joint_name>
  		<area>0.23</area>
  		<fluid_density>1.2041</fluid_density>
  		<forward>-1 0 0</forward>
  		<upward>0 1 0</upward>
  		<link_name>tail</link_name>
  		<fluidVelocity>${windType}</fluidVelocity>
    </plugin>

    <plugin name="usv_sail_plugin" filename="libfoil_dynamics_plugin.so">
      <link_type>keel</link_type>
      <a0>0</a0>
      <cla>10.0</cla>
      <cda>8.0</cda>
      <alpha_stall>0.785</alpha_stall>
      <cla_stall>-10.0</cla_stall>
      <cda_stall>-5.0</cda_stall>
      <cp>0 0 -0.15</cp>
      <area>1.0</area>
      <fluid_density>1000</fluid_density>
      <forward>1 0 0</forward>
      <upward>0 1 0</upward>
      <link_name>keel</link_name>
      <fluidVelocity>${waterType}</fluidVelocity>
    </plugin>


  <plugin name="usv_sail_plugin" filename="libfoil_dynamics_plugin.so">
		<link_type>rudder</link_type>
		<a0>0</a0>
		<cla>0.8</cla>
		<cda>0.3</cda>
		<alpha_stall>0.785</alpha_stall>
		<cla_stall>-0.85</cla_stall>
		<cda_stall>-0.3233984055</cda_stall>
		<cp>0 0 -0.15</cp>
		<area>1</area>
		<fluid_density>1000</fluid_density>
		<forward>1 0 0</forward>
		<upward>0 1 0</upward>
		<link_name>rudder</link_name>
		<fluidVelocity>${waterType}</fluidVelocity>
  </plugin>


	<plugin name="freefloating_gazebo_control" filename="libfreefloating_gazebo_control.so">
		<switchService>switch</switchService>
		<updateRate>100</updateRate>
		<link>base_link</link>
  	</plugin>


	<plugin name="usv_control" filename="libusv_control.so">
	 </plugin>

	<plugin name="usv_flap" filename="libusv_flap.so">
    <link_type>tail</link_type>
    <joint_name>tail_joint</joint_name>
		<Position>-15.0</Position>
	 </plugin>

  </gazebo>

</robot>
